<?xml version="1.0"?>
<robot xmlns:xacro="http://www.ros.org/wiki/xacro">

  <!-- Variáveis para as propriedades das rodas -->
  <xacro:property name="wheel_radius" value="0.05"/>
  <xacro:property name="wheel_length" value="0.02"/>

  <!-- Macro para criar rodas -->
  <xacro:macro name="wheel" params="wheel_name wheel_x wheel_y wheel_z wheel_rpy">
    
    <!-- Definição da roda -->
    <link name="${wheel_name}">
      <inertial>
        <mass value="5"/>
        <origin xyz="0 0 0"/>
        <inertia ixx="0.01" ixy="0" ixz="0" iyy="0.01" iyz="0" izz="0.01"/>
      </inertial>
      
      <visual>
        <geometry>
          <cylinder radius="${wheel_radius}" length="${wheel_length}"/>
        </geometry>
        <material name="black">
          <color rgba="0 1 0 0"/>
        </material>
      </visual>

      <collision>
        <geometry>
          <cylinder radius="${wheel_radius}" length="${wheel_length}"/>
        </geometry>
      </collision>
    </link>

    <!-- Definição da junta -->
    <joint name="${wheel_name}_joint" type="continuous">
      <parent link="base_link"/>
      <child link="${wheel_name}"/>
      <origin xyz="${wheel_x} ${wheel_y} ${wheel_z}" rpy="${wheel_rpy}"/>
      <axis xyz="0 0 1"/>
    </joint>
  </xacro:macro>
</robot>
